<?xml version="2.0">
<gazebo version="1.2">
    <model name="WBRobot">
    <static>true</static>
        <link name="chassis">
            <pose>0.0 0.0 0.15 0 0 0</pose>
            <inertial>
                <mass>10.0</mass>
            </inertial>
            <collision name="collision">
                <geometry>
                    <cylinder>
                        <radius>0.1</radius>
                        <length>0.2</length>
                    </cylinder>
                </geometry>
            </collision>
            <visual name="bottom">
                <pose>0 0 -0.1 0 0 0</pose>
                <geometry>
                    <cylinder>
                        <radius>0.1</radius>
                        <length>0.01</length>
                    </cylinder>
                </geometry>
                <material>
                    <script>Gazebo/Grey</script>
                </material>
            </visual>
            <visual name="middle">
                <pose>0 0 0.0 0 0 0</pose>
                <geometry>
                    <cylinder>
                        <radius>0.1</radius>
                        <length>0.01</length>
                    </cylinder>
                </geometry>
                <material>
                    <script>Gazebo/Grey</script>
                </material>
            </visual>
            <visual name="top">
                <pose>0 0 0.1 0 0 0</pose>
                <geometry>
                    <cylinder>
                        <radius>0.1</radius>
                        <length>0.01</length>
                    </cylinder>
                </geometry>
                <material>
                    <script>Gazebo/Grey</script>
                </material>
            </visual>
            <visual name="column1">
                <pose>-0.06 0.06 0 0 0 0</pose>
                <geometry>
                    <cylinder>
                        <radius>0.005</radius>
                        <length>0.2</length>
                    </cylinder>
                </geometry>
                <material>
                    <script>Gazebo/Grey</script>
                </material>
            </visual>
            <visual name="column2">
                <pose>-0.06 -0.06 0 0 0 0</pose>
                <geometry>
                    <cylinder>
                        <radius>0.005</radius>
                        <length>0.2</length>
                    </cylinder>
                </geometry>
                <material>
                    <script>Gazebo/Grey</script>
                </material>
            </visual>
            <visual name="column3">
                <pose>0.06 -0.06 0 0 0 0</pose>
                <geometry>
                    <cylinder>
                        <radius>0.005</radius>
                        <length>0.2</length>
                    </cylinder>
                </geometry>
                <material>
                    <script>Gazebo/Grey</script>
                </material>
            </visual>
            <visual name="column4">
                <pose>0.06 0.06 0 0 0 0</pose>
                <geometry>
                    <cylinder>
                        <radius>0.005</radius>
                        <length>0.2</length>
                    </cylinder>
                </geometry>
                <material>
                    <script>Gazebo/Grey</script>
                </material>
            </visual>
            <sensor name="IR1" type="ray">
                <pose>0.12 0.000000 0.000000 0.000000 -0.000000 0.000000</pose>
                <ray>
                    <scan>
                        <horizontal>
                            <samples>18</samples>
                            <resolution>1.000000</resolution>
                            <min_angle>-0.79</min_angle>
                            <max_angle>0.79</max_angle>
                        </horizontal>
                    </scan>
                    <range>
                        <min>0.050000</min>
                        <max>2.00000</max>
                        <resolution>0.360000</resolution>
                    </range>
                </ray>
                <always_on>true</always_on>
                <update_rate>10.000000</update_rate>
                <visualize>true</visualize>
            </sensor>
        </link>
        <link name="right_wheel">
            <pose>0 0.12 0.05 0 1.5707 1.5707</pose>
            <inertial>
                <inertia>
                    <ixx>0.001</ixx>
                    <ixy>0.0</ixy>
                    <ixz>0</ixz>
                    <iyy>0.001</iyy>
                    <iyz>0.0</iyz>
                    <izz>0.001</izz>
                </inertia>
                <mass>0.2</mass>
            </inertial>
            <collision name="collision">
                <geometry>
                    <cylinder>
                        <radius>0.05</radius>
                        <length>0.025</length>
                    </cylinder>
                </geometry>
                <surface>
                    <friction>
                        <ode>
                            <mu>100000.0</mu>
                            <mu2>100000.0</mu2>
                            <slip1>0.0</slip1>
                            <slip2>0.0</slip2>
                        </ode>
                    </friction>
                </surface>
            </collision>
            <visual name="visual">
                <geometry>
                    <cylinder>
                        <radius>0.05</radius>
                        <length>0.025</length>
                    </cylinder>
                </geometry>
                <material>
                    <script>Gazebo/FlatBlack</script>
                </material>
            </visual>
        </link>
        <link name="left_wheel">
            <pose>0 -0.12 0.05 0 1.5707 1.5707</pose>
            <inertial>
                <inertia>
                    <ixx>0.001</ixx>
                    <ixy>0.0</ixy>
                    <ixz>0</ixz>
                    <iyy>0.001</iyy>
                    <iyz>0.0</iyz>
                    <izz>0.001</izz>
                </inertia>
                <mass>0.2</mass>
            </inertial>
            <collision name="collision">
                <geometry>
                    <cylinder>
                        <radius>0.05</radius>
                        <length>0.025</length>
                    </cylinder>
                </geometry>
                <surface>
                    <friction>
                        <ode>
                            <mu>100000.0</mu>
                            <mu2>100000.0</mu2>
                            <slip1>0.0</slip1>
                            <slip2>0.0</slip2>
                        </ode>
                    </friction>
                </surface>
            </collision>
            <visual name="visual">
                <geometry>
                    <cylinder>
                        <radius>0.05</radius>
                        <length>0.025</length>
                    </cylinder>
                </geometry>
                <material>
                    <script>Gazebo/FlatBlack</script>
                </material>
            </visual>
        </link>
        <joint type="revolute" name="left_wheel_hinge">
            <pose>0 0 -0.05 0 0 0</pose>
            <child>left_wheel</child>
            <parent>chassis</parent>
            <axis>
                <xyz>0 1 0</xyz>
            </axis>
        </joint>
        <joint type="revolute" name="right_wheel_hinge">
            <pose>0 0 0.05 0 0 0</pose>
            <child>right_wheel</child>
            <parent>chassis</parent>
            <axis>
                <xyz>0 1 0</xyz>
            </axis>
        </joint>
        <plugin name="wbrobot" filename="libwbr_controller.so">
            <left_joint>left_wheel_hinge</left_joint>
            <right_joint>right_wheel_hinge</right_joint>
            <laser>IR1</laser>
            <torque>5</torque>
        </plugin>
        <static>false</static>
    </model>
</gazebo>
