<?xml version="1.0" ?>
<gazebo version="1.2">
    <model name="osrobot">
        <link name="chassis">
            <pose>0 0 0.2 0 0 0</pose>
            <collision name="collision">
                <geometry>
                    <box><size>0.525 0.295 0.03</size></box>
                </geometry>
            </collision>
            <visual name="visual">
                <geometry>
                    <box><size>0.525 0.295 0.03</size></box>
                </geometry>
                <material>
                    <script>
                        <uri>file://media/materials/scripts/gazebo.material</uri>
                        <name>Gazebo/GreenTransparent</name>
                    </script>
                </material>
            </visual>
            <sensor name="IR1" type="ray">
                <pose>0.28 0.0 0.00000 0.000000 -0.000000 0.000000</pose>
                <ray>
                    <scan>
                        <horizontal>
                            <samples>18</samples>
                            <resolution>1.000000</resolution>
                            <min_angle>-0.79</min_angle>
                            <max_angle>0.79</max_angle>
                        </horizontal>
                    </scan>
                    <range>
                        <min>0.050000</min>
                        <max>3.00000</max>
                        <resolution>0.360000</resolution>
                    </range>
                </ray>
                <always_on>true</always_on>
                <update_rate>10.000000</update_rate>
                <visualize>true</visualize>
            </sensor>

        </link>
        <link name="front_left_wheel">
            <pose>0.140 0.117 0.078 0 1.5707 1.5707</pose>
            <collision name="collision">
                <geometry>
                    <cylinder><radius>0.078</radius><length>0.06</length></cylinder>
                </geometry>
            </collision>
            <visual name="visual">
                <geometry>
                    <cylinder><radius>0.078</radius><length>0.06</length></cylinder>
                </geometry>
                <material>
                    <script>
                        <uri>file://media/materials/scripts/gazebo.material</uri>
                        <name>Gazebo/Grey</name>
                    </script>
                </material>
            </visual>
        </link>
        <link name="front_right_wheel">
            <pose>0.140 -0.117 0.078 0 1.5707 1.5707</pose>
            <collision name="collision">
                <geometry>
                    <cylinder><radius>0.078</radius><length>0.06</length></cylinder>
                </geometry>
            </collision>
            <visual name="visual">
                <geometry>
                    <cylinder><radius>0.078</radius><length>0.06</length></cylinder>
                </geometry>
                <material>
                    <script>
                        <uri>file://media/materials/scripts/gazebo.material</uri>
                        <name>Gazebo/Grey</name>
                    </script>
                </material>
            </visual>
        </link>
        <link name="back_right_wheel">
            <pose>-0.140 -0.117 0.078 0 1.5707 1.5707</pose>
            <collision name="collision">
                <geometry>
                    <cylinder><radius>0.078</radius><length>0.06</length></cylinder>
                </geometry>
            </collision>
            <visual name="visual">
                <geometry>
                    <cylinder><radius>0.078</radius><length>0.06</length></cylinder>
                </geometry>
                <material>
                    <script>
                        <uri>file://media/materials/scripts/gazebo.material</uri>
                        <name>Gazebo/Grey</name>
                    </script>
                </material>
            </visual>
        </link>
        <link name="back_left_wheel">
            <pose>-0.140 0.117 0.078 0 1.5707 1.5707</pose>
            <collision name="collision">
                <geometry>
                    <cylinder><radius>0.078</radius><length>0.06</length></cylinder>
                </geometry>
            </collision>
            <visual name="visual">
                <geometry>
                    <cylinder><radius>0.078</radius><length>0.06</length></cylinder>
                </geometry>
                <material>
                    <script>
                        <uri>file://media/materials/scripts/gazebo.material</uri>
                        <name>Gazebo/Grey</name>
                    </script>
                </material>
            </visual>
        </link>
        <joint type="revolute2" name="front_left_joint">
            <parent>chassis</parent>
            <child>front_left_wheel</child>
            <axis>
                <xyz>0 0 1</xyz>
                <limit>
                    <lower>0</lower>
                    <upper>0</upper>
                </limit>
            </axis>
            <axis2>
                <xyz>0 1 0</xyz>
            </axis2>
            <physics>
                <ode>
                    <limit><cfm>0.0</cfm><erp>0.9</erp></limit> 
                </ode>
            </physics>
        </joint>
        <joint type="revolute2" name="front_right_joint">
            <parent>chassis</parent>
            <child>front_right_wheel</child>
            <axis><xyz>0 0 1</xyz>
                <limit><lower>0</lower><upper>0</upper></limit>
            </axis>
            <axis2>
                <xyz>0 1 0</xyz>
            </axis2>
            <physics>
                <ode>
                    <limit><cfm>0.0</cfm><erp>0.9</erp></limit> 
                </ode>
            </physics>
        </joint>
        <joint type="revolute2" name="back_right_joint">
            <parent>chassis</parent>
            <child>back_right_wheel</child>
            <axis><xyz>0 0 1</xyz>
                <limit><lower>0</lower><upper>0</upper></limit>
            </axis>
            <axis2>
                <xyz>0 1 0</xyz>
            </axis2>
            <physics>
                <ode>
                    <limit><cfm>0.0</cfm><erp>0.9</erp></limit> 
                </ode>
            </physics>
        </joint>
        <joint type="revolute2" name="back_left_joint">
            <parent>chassis</parent>
            <child>back_left_wheel</child>
            <axis><xyz>0 0 1</xyz>
                <limit><lower>0</lower><upper>0</upper></limit>
            </axis>
            <axis2>
                <xyz>0 1 0</xyz>
            </axis2>
            <physics>
                <ode>
                    <limit><cfm>0.0</cfm><erp>0.9</erp></limit> 
                </ode>
            </physics>
        </joint>
    </model>
</gazebo>

