<?xml version="1.0" ?>
<gazebo version="1.2">
  <model name="car">
    <link name="chassis">
      <pose>0 0 0.3 0 0 0</pose>
      <collision name="collision">
        <geometry>
          <box><size>2.0 1.0 0.2</size></box>
        </geometry>
      </collision>
      <visual name="visual">
        <geometry>
          <box><size>2.0 1.0 0.2</size></box>
        </geometry>
        <material>
          <script>
            <uri>file://media/materials/scripts/gazebo.material</uri>
            <name>Gazebo/Green</name>
          </script>
        </material>
      </visual>
    </link>
    <link name="front_left_wheel">
      <pose>0.8 0.6 0.3 0 1.5707 1.5707</pose>
      <collision name="collision">
        <geometry>
          <cylinder><radius>0.3</radius><length>0.1</length></cylinder>
        </geometry>
      </collision>
      <visual name="visual">
        <geometry>
          <cylinder><radius>0.3</radius><length>0.1</length></cylinder>
        </geometry>
        <material>
          <script>
            <uri>file://media/materials/scripts/gazebo.material</uri>
            <name>Gazebo/Black</name>
          </script>
        </material>
      </visual>
    </link>
    <link name="front_right_wheel">
      <pose>0.8 -0.6 0.3 0 1.5707 1.5707</pose>
      <collision name="collision">
        <geometry>
          <cylinder><radius>0.3</radius><length>0.1</length></cylinder>
        </geometry>
      </collision>
      <visual name="visual">
        <geometry>
          <cylinder><radius>0.3</radius><length>0.1</length></cylinder>
        </geometry>
        <material>
          <script>
            <uri>file://media/materials/scripts/gazebo.material</uri>
            <name>Gazebo/Black</name>
        </script>
      </material>
      </visual>
    </link>
    <link name="back_right_wheel">
      <pose>-0.8 -0.6 0.3 0 1.5707 1.5707</pose>
      <collision name="collision">
        <geometry>
          <cylinder><radius>0.3</radius><length>0.1</length></cylinder>
        </geometry>
      </collision>
      <visual name="visual">
        <geometry>
          <cylinder><radius>0.3</radius><length>0.1</length></cylinder>
        </geometry>
        <material>
          <script>
            <uri>file://media/materials/scripts/gazebo.material</uri>
            <name>Gazebo/Black</name>
        </script>
      </material>
      </visual>
    </link>
    <link name="back_left_wheel">
      <pose>-0.8 0.6 0.3 0 1.5707 1.5707</pose>
      <collision name="collision">
        <geometry>
          <cylinder><radius>0.3</radius><length>0.1</length></cylinder>
        </geometry>
      </collision>
      <visual name="visual">
        <geometry>
          <cylinder><radius>0.3</radius><length>0.1</length></cylinder>
        </geometry>
        <material>
          <script>
            <uri>file://media/materials/scripts/gazebo.material</uri>
            <name>Gazebo/Black</name>
        </script>
      </material>
      </visual>
    </link>
    <joint type="revolute2" name="front_left_joint">
      <parent>chassis</parent>
      <child>front_left_wheel</child>
      <axis>
        <xyz>0 0 1</xyz>
        <limit>
          <lower>0</lower>
          <upper>0</upper>
        </limit>
      </axis>
      <axis2>
        <xyz>0 1 0</xyz>
      </axis2>
      <physics>
        <ode>
          <limit><cfm>0.0</cfm><erp>0.9</erp></limit> 
        </ode>
      </physics>
    </joint>
    <joint type="revolute2" name="front_right_joint">
      <parent>chassis</parent>
      <child>front_right_wheel</child>
      <axis><xyz>0 0 1</xyz>
        <limit><lower>0</lower><upper>0</upper></limit>
      </axis>
      <axis2>
        <xyz>0 1 0</xyz>
      </axis2>
      <physics>
        <ode>
          <limit><cfm>0.0</cfm><erp>0.9</erp></limit> 
        </ode>
      </physics>
    </joint>
    <joint type="revolute2" name="back_right_joint">
      <parent>chassis</parent>
      <child>back_right_wheel</child>
      <axis><xyz>0 0 1</xyz>
        <limit><lower>0</lower><upper>0</upper></limit>
      </axis>
      <axis2>
        <xyz>0 1 0</xyz>
      </axis2>
      <physics>
        <ode>
          <limit><cfm>0.0</cfm><erp>0.9</erp></limit> 
        </ode>
      </physics>
    </joint>
    <joint type="revolute2" name="back_left_joint">
      <parent>chassis</parent>
      <child>back_left_wheel</child>
      <axis><xyz>0 0 1</xyz>
        <limit><lower>0</lower><upper>0</upper></limit>
      </axis>
      <axis2>
        <xyz>0 1 0</xyz>
      </axis2>
      <physics>
        <ode>
          <limit><cfm>0.0</cfm><erp>0.9</erp></limit> 
        </ode>
      </physics>
    </joint>
    </model>
</gazebo>

